Workbook

Sheet حسين المغلق
A1: المبالغ على حسين المغلق
A3: الشهر | B3: التاريخ | C3: الوصف | D3: مبلغ الأجار | E3: ملاحظات
A4: أغسطس 2026 | B4: 46250 | C4: المصروفات الشهرية المشتركة | D4: ='أغسطس 2026'!C43 -> 850
C5: مبالغ مسترجعة لحسين | D5: ='أغسطس 2026'!C32*-1 -> 0
B6: 46250 | C6: مبلغ مدفوع | D6: -850
A10: سبتمبر 2026
B11: 46266 | C11: المصروفات الشهرية المشتركة | D11: ='سبتمبر 2026'!C43 -> 0
C12: مبالغ مسترجعة لحسين | D12: ='سبتمبر 2026'!C32*-1 -> 0
C13: مبلغ مدفوع
A18: أكتوبر 2026
B19: 46296 | C19: المصروفات الشهرية المشتركة | D19: ='أكتوبر 2026'!C43 -> 0
C20: مبالغ مسترجعة لحسين | D20: ='أكتوبر 2026'!C32*-1 -> 0
C21: مبلغ مدفوع
A26: نوفمبر 2026
B27: 46327 | C27: المصروفات الشهرية المشتركة | D27: ='نوفمبر 2026'!C43 -> 0
C28: مبالغ مسترجعة لحسين | D28: ='نوفمبر 2026'!C32*-1 -> 0
C29: مبلغ مدفوع
A34: ديسمبر 2026
B35: 46357 | C35: المصروفات الشهرية المشتركة | D35: ='ديسمبر 2026'!C43 -> 0
C36: مبالغ مسترجعة لحسين | D36: ='ديسمبر 2026'!C32*-1 -> 0
C37: مبلغ مدفوع
A43: يناير 2027
B44: 46388 | C44: المصروفات الشهرية المشتركة | D44: ='يناير 2027'!C43 -> 0
C45: مبالغ مسترجعة لحسين | D45: ='يناير 2027'!C32*-1 -> 0
C46: مبلغ مدفوع
A52: فبراير 2027
B53: 46419 | C53: المصروفات الشهرية المشتركة | D53: ='فبراير 2027'!C43 -> 0
C54: مبالغ مسترجعة لحسين | D54: ='فبراير 2027'!C32*-1 -> 0
C55: مبلغ مدفوع
A61: مارس 2027
B62: 46447 | C62: المصروفات الشهرية المشتركة | D62: ='مارس 2027'!C43 -> 0
C63: مبالغ مسترجعة لحسين | D63: ='مارس 2027'!C32*-1 -> 0
C64: مبلغ مدفوع
A71: أبريل 2027
B72: 46478 | C72: المصروفات الشهرية المشتركة | D72: ='أبريل 2027'!C43 -> 0
C73: مبالغ مسترجعة لحسين | D73: ='أبريل 2027'!C32*-1 -> 0
C74: مبلغ مدفوع
A81: مايو 2027
B82: 46508 | C82: المصروفات الشهرية المشتركة | D82: ='مارس 2027'!C43 -> 0
C83: مبالغ مسترجعة لحسين | D83: ='مارس 2027'!C32*-1 -> 0
...

Sheet محمد قريش
A1: المبالغ على محمد قريش
A3: الشهر | B3: التاريخ | C3: الوصف | D3: مبلغ الأجار | E3: ملاحظات
A4: أغسطس 2026 | B4: 46250 | C4: المصروفات الشهرية المشتركة | D4: ='أغسطس 2026'!C43 -> 850
C5: مبالغ مسترجعة لمحمد | D5: ='أغسطس 2026'!C16*-1 -> -1700
B6: 46250 | C6: مبلغ مدفوع | D6: -850
A10: سبتمبر 2026
B11: 46266 | C11: المصروفات الشهرية المشتركة | D11: ='سبتمبر 2026'!C43 -> 0
C12: مبالغ مسترجعة لمحمد | D12: ='سبتمبر 2026'!C16*-1 -> 0
C13: مبلغ مدفوع
A18: أكتوبر 2026
B19: 46296 | C19: المصروفات الشهرية المشتركة | D19: ='أكتوبر 2026'!C43 -> 0
C20: مبالغ مسترجعة لمحمد | D20: ='أكتوبر 2026'!C16*-1 -> 0
C21: مبلغ مدفوع
A26: نوفمبر 2026
B27: 46327 | C27: المصروفات الشهرية المشتركة | D27: ='نوفمبر 2026'!C43 -> 0
C28: مبالغ مسترجعة لمحمد | D28: ='نوفمبر 2026'!C16*-1 -> 0
C29: مبلغ مدفوع
A34: ديسمبر 2026
B35: 46357 | C35: المصروفات الشهرية المشتركة | D35: ='ديسمبر 2026'!C43 -> 0
C36: مبالغ مسترجعة لمحمد | D36: ='ديسمبر 2026'!C16*-1 -> 0
C37: مبلغ مدفوع
A43: يناير 2027
B44: 46388 | C44: المصروفات الشهرية المشتركة | D44: ='يناير 2027'!C43 -> 0
C45: مبالغ مسترجعة لمحمد | D45: ='يناير 2027'!C16*-1 -> 0
C46: مبلغ مدفوع
A52: فبراير 2027
B53: 46419 | C53: المصروفات الشهرية المشتركة | D53: ='فبراير 2027'!C43 -> 0
C54: مبالغ مسترجعة لمحمد | D54: ='فبراير 2027'!C16*-1 -> 0
C55: مبلغ مدفوع
A61: مارس 2027
B62: 46447 | C62: المصروفات الشهرية المشتركة | D62: ='مارس 2027'!C43 -> 0
C63: مبالغ مسترجعة لمحمد | D63: ='مارس 2027'!C16*-1 -> 0
C64: مبلغ مدفوع
A71: أبريل 2027
B72: 46478 | C72: المصروفات الشهرية المشتركة | D72: ='أبريل 2027'!C43 -> 0
C73: مبالغ مسترجعة لمحمد | D73: ='أبريل 2027'!C16*-1 -> 0
C74: مبلغ مدفوع
A81: مايو 2027
B82: 46508 | C82: المصروفات الشهرية المشتركة | D82: ='مارس 2027'!C43 -> 0
C83: مبالغ مسترجعة لمحمد | D83: ='مارس 2027'!C16*-1 -> 0
...

Sheet أغسطس 2026
A1: أغسطس 2026
A5: مدفوعات محمد قريش
A7: التاريخ | B7: الوصف | C7: المبلغ | D7: دفع بواسطة
A8: 46250 | B8: أجار الشقة - من 21 أغسطس 2026 | C8: 1700 | D8: محمد قريش
B16: المجموع | C16: =SUM(C8:C15) -> 1700
A21: مدفوعات حسين المغلق
A23: التاريخ | B23: الوصف | C23: المبلغ | D23: دفع بواسطة
B32: المجموع | C32: =SUM(C24:C31) -> 0
B42: المجموع الكلي | C42: =C16+C32 -> 1700
B43: القطة على كل شخص (شخصين) | C43: =C42/2 -> 850

Sheet سبتمبر 2026
A1: سبتمبر 2026
A5: مدفوعات محمد قريش
A7: التاريخ | B7: الوصف | C7: المبلغ | D7: دفع بواسطة
D8: محمد قريش
B16: المجموع | C16: =SUM(C8:C15) -> 0
A21: مدفوعات حسين المغلق
A23: التاريخ | B23: الوصف | C23: المبلغ | D23: دفع بواسطة
B32: المجموع | C32: =SUM(C24:C31) -> 0
B42: المجموع الكلي | C42: =C16+C32 -> 0
B43: القطة على كل شخص (شخصين) | C43: =C42/2 -> 0

Sheet أكتوبر 2026
A1: أكتوبر 2026
A5: مدفوعات محمد قريش
A7: التاريخ | B7: الوصف | C7: المبلغ | D7: دفع بواسطة
D8: محمد قريش
B16: المجموع | C16: =SUM(C8:C15) -> 0
A21: مدفوعات حسين المغلق
A23: التاريخ | B23: الوصف | C23: المبلغ | D23: دفع بواسطة
B32: المجموع | C32: =SUM(C24:C31) -> 0
B42: المجموع الكلي | C42: =C16+C32 -> 0
B43: القطة على كل شخص (شخصين) | C43: =C42/2 -> 0

Sheet نوفمبر 2026
A1: نوفمبر 2026
A5: مدفوعات محمد قريش
A7: التاريخ | B7: الوصف | C7: المبلغ | D7: دفع بواسطة
D8: محمد قريش
B16: المجموع | C16: =SUM(C8:C15) -> 0
A21: مدفوعات حسين المغلق
A23: التاريخ | B23: الوصف | C23: المبلغ | D23: دفع بواسطة
B32: المجموع | C32: =SUM(C24:C31) -> 0
B42: المجموع الكلي | C42: =C16+C32 -> 0
B43: القطة على كل شخص (شخصين) | C43: =C42/2 -> 0

Sheet ديسمبر 2026
A1: ديسمبر 2026
A5: مدفوعات محمد قريش
A7: التاريخ | B7: الوصف | C7: المبلغ | D7: دفع بواسطة
D8: محمد قريش
B16: المجموع | C16: =SUM(C8:C15) -> 0
A21: مدفوعات حسين المغلق
A23: التاريخ | B23: الوصف | C23: المبلغ | D23: دفع بواسطة
B32: المجموع | C32: =SUM(C24:C31) -> 0
B42: المجموع الكلي | C42: =C16+C32 -> 0
B43: القطة على كل شخص (شخصين) | C43: =C42/2 -> 0

Sheet يناير 2027
A1: يناير 2027
A5: مدفوعات محمد قريش
A7: التاريخ | B7: الوصف | C7: المبلغ | D7: دفع بواسطة
D8: محمد قريش
B16: المجموع | C16: =SUM(C8:C15) -> 0
A21: مدفوعات حسين المغلق
A23: التاريخ | B23: الوصف | C23: المبلغ | D23: دفع بواسطة
B32: المجموع | C32: =SUM(C24:C31) -> 0
B42: المجموع الكلي | C42: =C16+C32 -> 0
B43: القطة على كل شخص (شخصين) | C43: =C42/2 -> 0

Sheet فبراير 2027
A1: فبراير 2027
A5: مدفوعات محمد قريش
A7: التاريخ | B7: الوصف | C7: المبلغ | D7: دفع بواسطة
D8: محمد قريش
B16: المجموع | C16: =SUM(C8:C15) -> 0
A21: مدفوعات حسين المغلق
A23: التاريخ | B23: الوصف | C23: المبلغ | D23: دفع بواسطة
B32: المجموع | C32: =SUM(C24:C31) -> 0
B42: المجموع الكلي | C42: =C16+C32 -> 0
B43: القطة على كل شخص (شخصين) | C43: =C42/2 -> 0

Sheet مارس 2027
A1: مارس 2027
A5: مدفوعات محمد قريش
A7: التاريخ | B7: الوصف | C7: المبلغ | D7: دفع بواسطة
D8: محمد قريش
B16: المجموع | C16: =SUM(C8:C15) -> 0
A21: مدفوعات حسين المغلق
A23: التاريخ | B23: الوصف | C23: المبلغ | D23: دفع بواسطة
B32: المجموع | C32: =SUM(C24:C31) -> 0
B42: المجموع الكلي | C42: =C16+C32 -> 0
B43: القطة على كل شخص (شخصين) | C43: =C42/2 -> 0

Sheet أبريل 2027
A1: أبريل 2027
A5: مدفوعات محمد قريش
A7: التاريخ | B7: الوصف | C7: المبلغ | D7: دفع بواسطة
D8: محمد قريش
B16: المجموع | C16: =SUM(C8:C15) -> 0
A21: مدفوعات حسين المغلق
A23: التاريخ | B23: الوصف | C23: المبلغ | D23: دفع بواسطة
B32: المجموع | C32: =SUM(C24:C31) -> 0
B42: المجموع الكلي | C42: =C16+C32 -> 0
B43: القطة على كل شخص (شخصين) | C43: =C42/2 -> 0

Sheet مايو 2027
A1: مايو 2027
A5: مدفوعات محمد قريش
A7: التاريخ | B7: الوصف | C7: المبلغ | D7: دفع بواسطة
D8: محمد قريش
B16: المجموع | C16: =SUM(C8:C15) -> 0
A21: مدفوعات حسين المغلق
A23: التاريخ | B23: الوصف | C23: المبلغ | D23: دفع بواسطة
B32: المجموع | C32: =SUM(C24:C31) -> 0
B42: المجموع الكلي | C42: =C16+C32 -> 0
B43: القطة على كل شخص (شخصين) | C43: =C42/2 -> 0

Sheet يونيو 2027
A1: يونيو 2027
A5: مدفوعات محمد قريش | B5: يونيو 2027
A7: التاريخ | B7: الوصف | C7: المبلغ | D7: دفع بواسطة
D8: محمد قريش
B16: المجموع | C16: =SUM(C8:C15) -> 0
A21: مدفوعات حسين المغلق
A23: التاريخ | B23: الوصف | C23: المبلغ | D23: دفع بواسطة
B32: المجموع | C32: =SUM(C24:C31) -> 0
B42: المجموع الكلي | C42: =C16+C32 -> 0
B43: القطة على كل شخص (شخصين) | C43: =C42/2 -> 0

Sheet يوليو 2027
A1: يوليو 2027
A5: مدفوعات محمد قريش | B5: يونيو 2027
A7: التاريخ | B7: الوصف | C7: المبلغ | D7: دفع بواسطة
D8: محمد قريش
B16: المجموع | C16: =SUM(C8:C15) -> 0
A21: مدفوعات حسين المغلق
A23: التاريخ | B23: الوصف | C23: المبلغ | D23: دفع بواسطة
B32: المجموع | C32: =SUM(C24:C31) -> 0
B42: المجموع الكلي | C42: =C16+C32 -> 0
B43: القطة على كل شخص (شخصين) | C43: =C42/2 -> 0

Sheet أغسطس 2027
A1: أغسطس 2027
A5: مدفوعات محمد قريش | B5: يونيو 2027
A7: التاريخ | B7: الوصف | C7: المبلغ | D7: دفع بواسطة
D8: محمد قريش
B16: المجموع | C16: =SUM(C8:C15) -> 0
A21: مدفوعات حسين المغلق
A23: التاريخ | B23: الوصف | C23: المبلغ | D23: دفع بواسطة
B32: المجموع | C32: =SUM(C24:C31) -> 0
B42: المجموع الكلي | C42: =C16+C32 -> 0
B43: القطة على كل شخص (شخصين) | C43: =C42/2 -> 0
